Error: Triple:189840
Traceback (most recent call last):
  File "getResources.py", line 165, in processTriple
    g.parse(data=line,format="nquads")
  File "/usr/local/lib/python2.7/dist-packages/rdflib-4.2.2-py2.7.egg/rdflib/graph.py", line 1492, in parse
    context.parse(source, publicID=publicID, format=format, **args)
  File "/usr/local/lib/python2.7/dist-packages/rdflib-4.2.2-py2.7.egg/rdflib/graph.py", line 1039, in parse
    parser.parse(source, self, **args)
  File "/usr/local/lib/python2.7/dist-packages/rdflib-4.2.2-py2.7.egg/rdflib/plugins/parsers/nquads.py", line 66, in parse
    raise ParseError("Invalid line (%s):\n%r" % (msg, __line))
ParseError: Invalid line (Failed to eat _:([A-Za-z0-9]*) at _pinyin <http://linkedgeodata.org/data/triplify/node26036352> .):
u'<http://linkedgeodata.org/triplify/node26036352> <http://www.w3.org/2000/01/rdf-schema#label> "F\\u0113il\\u01DCb\\u012Bn"@zh_pinyin <http://linkedgeodata.org/data/triplify/node26036352> .'

Error: Triple:190122
Traceback (most recent call last):
  File "getResources.py", line 165, in processTriple
    g.parse(data=line,format="nquads")
  File "/usr/local/lib/python2.7/dist-packages/rdflib-4.2.2-py2.7.egg/rdflib/graph.py", line 1492, in parse
    context.parse(source, publicID=publicID, format=format, **args)
  File "/usr/local/lib/python2.7/dist-packages/rdflib-4.2.2-py2.7.egg/rdflib/graph.py", line 1039, in parse
    parser.parse(source, self, **args)
  File "/usr/local/lib/python2.7/dist-packages/rdflib-4.2.2-py2.7.egg/rdflib/plugins/parsers/nquads.py", line 66, in parse
    raise ParseError("Invalid line (%s):\n%r" % (msg, __line))
ParseError: Invalid line (Failed to eat [ \t]*\.[ \t]*(#.*)? at * <http://bnb.data.bl.uk/doc/resource/006893251.rdf?_metadata=all,views,formats,execution,bindings,site> .):
u'_:httpx3Ax2Fx2Fbnbx2Edatax2Eblx2Eukx2Fdocx2Fresourcex2F006893251x2Erdfx3Fx5Fmetadatax3Dallx2Cviewsx2Cformatsx2Cex78ecutionx2Cbindingsx2Csitexxex78ecution <http://purl.org/linked-data/api/vocab#termBinding> _:httpx3Ax2Fx2Fbnbx2Edatax2Eblx2Eukx2Fdocx2Fresourcex2F006893251x2Erdfx3Fx5Fmetadatax3Dallx2Cviewsx2Cformatsx2Cex78ecutionx2Cbindingsx2Csitexxtermx5F* <http://bnb.data.bl.uk/doc/resource/006893251.rdf?_metadata=all,views,formats,execution,bindings,site> .'

Error: Triple:190158
Traceback (most recent call last):
  File "getResources.py", line 165, in processTriple
    g.parse(data=line,format="nquads")
  File "/usr/local/lib/python2.7/dist-packages/rdflib-4.2.2-py2.7.egg/rdflib/graph.py", line 1492, in parse
    context.parse(source, publicID=publicID, format=format, **args)
  File "/usr/local/lib/python2.7/dist-packages/rdflib-4.2.2-py2.7.egg/rdflib/graph.py", line 1039, in parse
    parser.parse(source, self, **args)
  File "/usr/local/lib/python2.7/dist-packages/rdflib-4.2.2-py2.7.egg/rdflib/plugins/parsers/nquads.py", line 66, in parse
    raise ParseError("Invalid line (%s):\n%r" % (msg, __line))
ParseError: Invalid line (Predicate must be uriref):
u'_:httpx3Ax2Fx2Fbnbx2Edatax2Eblx2Eukx2Fdocx2Fresourcex2F006893251x2Erdfx3Fx5Fmetadatax3Dallx2Cviewsx2Cformatsx2Cex78ecutionx2Cbindingsx2Csitexxtermx5F* <http://purl.org/linked-data/api/vocab#label> "*" <http://bnb.data.bl.uk/doc/resource/006893251.rdf?_metadata=all,views,formats,execution,bindings,site> .'

Error: Triple:190158
Traceback (most recent call last):
  File "getResources.py", line 165, in processTriple
    g.parse(data=line,format="nquads")
  File "/usr/local/lib/python2.7/dist-packages/rdflib-4.2.2-py2.7.egg/rdflib/graph.py", line 1492, in parse
    context.parse(source, publicID=publicID, format=format, **args)
  File "/usr/local/lib/python2.7/dist-packages/rdflib-4.2.2-py2.7.egg/rdflib/graph.py", line 1039, in parse
    parser.parse(source, self, **args)
  File "/usr/local/lib/python2.7/dist-packages/rdflib-4.2.2-py2.7.egg/rdflib/plugins/parsers/nquads.py", line 66, in parse
    raise ParseError("Invalid line (%s):\n%r" % (msg, __line))
ParseError: Invalid line (Predicate must be uriref):
u'_:httpx3Ax2Fx2Fbnbx2Edatax2Eblx2Eukx2Fdocx2Fresourcex2F006893251x2Erdfx3Fx5Fmetadatax3Dallx2Cviewsx2Cformatsx2Cex78ecutionx2Cbindingsx2Csitexxtermx5F* <http://purl.org/linked-data/api/vocab#property> <http://purl.org/linked-data/api/vocab#allProperties> <http://bnb.data.bl.uk/doc/resource/006893251.rdf?_metadata=all,views,formats,execution,bindings,site> .'

Error: Triple:503563
Traceback (most recent call last):
  File "getResources.py", line 165, in processTriple
    g.parse(data=line,format="nquads")
  File "/usr/local/lib/python2.7/dist-packages/rdflib-4.2.2-py2.7.egg/rdflib/graph.py", line 1492, in parse
    context.parse(source, publicID=publicID, format=format, **args)
  File "/usr/local/lib/python2.7/dist-packages/rdflib-4.2.2-py2.7.egg/rdflib/graph.py", line 1039, in parse
    parser.parse(source, self, **args)
  File "/usr/local/lib/python2.7/dist-packages/rdflib-4.2.2-py2.7.egg/rdflib/plugins/parsers/nquads.py", line 64, in parse
    self.parseline()
  File "/usr/local/lib/python2.7/dist-packages/rdflib-4.2.2-py2.7.egg/rdflib/plugins/parsers/nquads.py", line 81, in parseline
    obj = self.object()
  File "/usr/local/lib/python2.7/dist-packages/rdflib-4.2.2-py2.7.egg/rdflib/plugins/parsers/ntriples.py", line 228, in object
    objt = self.uriref() or self.nodeid() or self.literal()
  File "/usr/local/lib/python2.7/dist-packages/rdflib-4.2.2-py2.7.egg/rdflib/plugins/parsers/ntriples.py", line 238, in uriref
    return URI(uri)
  File "/usr/local/lib/python2.7/dist-packages/rdflib-4.2.2-py2.7.egg/rdflib/term.py", line 224, in __new__
    logger.warning('%s does not look like a valid URI, trying to serialize this will break.'%value)
  File "/usr/lib/python2.7/logging/__init__.py", line 1164, in warning
    self._log(WARNING, msg, args, **kwargs)
  File "/usr/lib/python2.7/logging/__init__.py", line 1271, in _log
    self.handle(record)
  File "/usr/lib/python2.7/logging/__init__.py", line 1281, in handle
    self.callHandlers(record)
  File "/usr/lib/python2.7/logging/__init__.py", line 1328, in callHandlers
    " \"%s\"\n" % self.name)
IOError: [Errno 5] Input/output error

Error: Triple:562857
Traceback (most recent call last):
  File "getResources.py", line 165, in processTriple
    g.parse(data=line,format="nquads")
  File "/usr/local/lib/python2.7/dist-packages/rdflib-4.2.2-py2.7.egg/rdflib/graph.py", line 1492, in parse
    context.parse(source, publicID=publicID, format=format, **args)
  File "/usr/local/lib/python2.7/dist-packages/rdflib-4.2.2-py2.7.egg/rdflib/graph.py", line 1039, in parse
    parser.parse(source, self, **args)
  File "/usr/local/lib/python2.7/dist-packages/rdflib-4.2.2-py2.7.egg/rdflib/plugins/parsers/nquads.py", line 66, in parse
    raise ParseError("Invalid line (%s):\n%r" % (msg, __line))
ParseError: Invalid line (Failed to eat [ \t]*\.[ \t]*(#.*)? at * <http://bnb.data.bl.uk/doc/resource/006893251.rdf?_metadata=all,views,formats,execution,bindings,site&_view=resourceViewer> .):
u'_:httpx3Ax2Fx2Fbnbx2Edatax2Eblx2Eukx2Fdocx2Fresourcex2F006893251x2Erdfx3Fx5Fmetadatax3Dallx2Cviewsx2Cformatsx2Cex78ecutionx2Cbindingsx2Csitex26x5Fviewx3DresourceViewerxxex78ecution <http://purl.org/linked-data/api/vocab#termBinding> _:httpx3Ax2Fx2Fbnbx2Edatax2Eblx2Eukx2Fdocx2Fresourcex2F006893251x2Erdfx3Fx5Fmetadatax3Dallx2Cviewsx2Cformatsx2Cex78ecutionx2Cbindingsx2Csitex26x5Fviewx3DresourceViewerxxtermx5F* <http://bnb.data.bl.uk/doc/resource/006893251.rdf?_metadata=all,views,formats,execution,bindings,site&_view=resourceViewer> .'

Error: Triple:562929
Traceback (most recent call last):
  File "getResources.py", line 165, in processTriple
    g.parse(data=line,format="nquads")
  File "/usr/local/lib/python2.7/dist-packages/rdflib-4.2.2-py2.7.egg/rdflib/graph.py", line 1492, in parse
    context.parse(source, publicID=publicID, format=format, **args)
  File "/usr/local/lib/python2.7/dist-packages/rdflib-4.2.2-py2.7.egg/rdflib/graph.py", line 1039, in parse
    parser.parse(source, self, **args)
  File "/usr/local/lib/python2.7/dist-packages/rdflib-4.2.2-py2.7.egg/rdflib/plugins/parsers/nquads.py", line 66, in parse
    raise ParseError("Invalid line (%s):\n%r" % (msg, __line))
ParseError: Invalid line (Predicate must be uriref):
u'_:httpx3Ax2Fx2Fbnbx2Edatax2Eblx2Eukx2Fdocx2Fresourcex2F006893251x2Erdfx3Fx5Fmetadatax3Dallx2Cviewsx2Cformatsx2Cex78ecutionx2Cbindingsx2Csitex26x5Fviewx3DresourceViewerxxtermx5F* <http://purl.org/linked-data/api/vocab#label> "*" <http://bnb.data.bl.uk/doc/resource/006893251.rdf?_metadata=all,views,formats,execution,bindings,site&_view=resourceViewer> .'

Error: Triple:562929
Traceback (most recent call last):
  File "getResources.py", line 165, in processTriple
    g.parse(data=line,format="nquads")
  File "/usr/local/lib/python2.7/dist-packages/rdflib-4.2.2-py2.7.egg/rdflib/graph.py", line 1492, in parse
    context.parse(source, publicID=publicID, format=format, **args)
  File "/usr/local/lib/python2.7/dist-packages/rdflib-4.2.2-py2.7.egg/rdflib/graph.py", line 1039, in parse
    parser.parse(source, self, **args)
  File "/usr/local/lib/python2.7/dist-packages/rdflib-4.2.2-py2.7.egg/rdflib/plugins/parsers/nquads.py", line 66, in parse
    raise ParseError("Invalid line (%s):\n%r" % (msg, __line))
ParseError: Invalid line (Predicate must be uriref):
u'_:httpx3Ax2Fx2Fbnbx2Edatax2Eblx2Eukx2Fdocx2Fresourcex2F006893251x2Erdfx3Fx5Fmetadatax3Dallx2Cviewsx2Cformatsx2Cex78ecutionx2Cbindingsx2Csitex26x5Fviewx3DresourceViewerxxtermx5F* <http://purl.org/linked-data/api/vocab#property> <http://purl.org/linked-data/api/vocab#allProperties> <http://bnb.data.bl.uk/doc/resource/006893251.rdf?_metadata=all,views,formats,execution,bindings,site&_view=resourceViewer> .'

Error: Triple:655423
Traceback (most recent call last):
  File "getResources.py", line 165, in processTriple
    g.parse(data=line,format="nquads")
  File "/usr/local/lib/python2.7/dist-packages/rdflib-4.2.2-py2.7.egg/rdflib/graph.py", line 1492, in parse
    context.parse(source, publicID=publicID, format=format, **args)
  File "/usr/local/lib/python2.7/dist-packages/rdflib-4.2.2-py2.7.egg/rdflib/graph.py", line 1039, in parse
    parser.parse(source, self, **args)
  File "/usr/local/lib/python2.7/dist-packages/rdflib-4.2.2-py2.7.egg/rdflib/plugins/parsers/nquads.py", line 66, in parse
    raise ParseError("Invalid line (%s):\n%r" % (msg, __line))
ParseError: Invalid line (Failed to eat _:([A-Za-z0-9]*) at _pinyin <http://linkedgeodata.org/data/triplify/node424310680> .):
u'<http://linkedgeodata.org/triplify/node424310680> <http://www.w3.org/2000/01/rdf-schema#label> "S\\u012Bw\\u0113ish\\u00ECl\\u00E1n"@zh_pinyin <http://linkedgeodata.org/data/triplify/node424310680> .'

Error: Triple:810823
Traceback (most recent call last):
  File "getResources.py", line 165, in processTriple
    g.parse(data=line,format="nquads")
  File "/usr/local/lib/python2.7/dist-packages/rdflib-4.2.2-py2.7.egg/rdflib/graph.py", line 1492, in parse
    context.parse(source, publicID=publicID, format=format, **args)
  File "/usr/local/lib/python2.7/dist-packages/rdflib-4.2.2-py2.7.egg/rdflib/graph.py", line 1039, in parse
    parser.parse(source, self, **args)
  File "/usr/local/lib/python2.7/dist-packages/rdflib-4.2.2-py2.7.egg/rdflib/plugins/parsers/nquads.py", line 64, in parse
    self.parseline()
  File "/usr/local/lib/python2.7/dist-packages/rdflib-4.2.2-py2.7.egg/rdflib/plugins/parsers/nquads.py", line 78, in parseline
    predicate = self.predicate()
  File "/usr/local/lib/python2.7/dist-packages/rdflib-4.2.2-py2.7.egg/rdflib/plugins/parsers/ntriples.py", line 222, in predicate
    pred = self.uriref()
  File "/usr/local/lib/python2.7/dist-packages/rdflib-4.2.2-py2.7.egg/rdflib/plugins/parsers/ntriples.py", line 238, in uriref
    return URI(uri)
  File "/usr/local/lib/python2.7/dist-packages/rdflib-4.2.2-py2.7.egg/rdflib/term.py", line 224, in __new__
    logger.warning('%s does not look like a valid URI, trying to serialize this will break.'%value)
  File "/usr/lib/python2.7/logging/__init__.py", line 1164, in warning
    self._log(WARNING, msg, args, **kwargs)
  File "/usr/lib/python2.7/logging/__init__.py", line 1271, in _log
    self.handle(record)
  File "/usr/lib/python2.7/logging/__init__.py", line 1281, in handle
    self.callHandlers(record)
  File "/usr/lib/python2.7/logging/__init__.py", line 1328, in callHandlers
    " \"%s\"\n" % self.name)
IOError: [Errno 5] Input/output error

Error: Triple:810823
Traceback (most recent call last):
  File "getResources.py", line 165, in processTriple
    g.parse(data=line,format="nquads")
  File "/usr/local/lib/python2.7/dist-packages/rdflib-4.2.2-py2.7.egg/rdflib/graph.py", line 1492, in parse
    context.parse(source, publicID=publicID, format=format, **args)
  File "/usr/local/lib/python2.7/dist-packages/rdflib-4.2.2-py2.7.egg/rdflib/graph.py", line 1039, in parse
    parser.parse(source, self, **args)
  File "/usr/local/lib/python2.7/dist-packages/rdflib-4.2.2-py2.7.egg/rdflib/plugins/parsers/nquads.py", line 64, in parse
    self.parseline()
  File "/usr/local/lib/python2.7/dist-packages/rdflib-4.2.2-py2.7.egg/rdflib/plugins/parsers/nquads.py", line 78, in parseline
    predicate = self.predicate()
  File "/usr/local/lib/python2.7/dist-packages/rdflib-4.2.2-py2.7.egg/rdflib/plugins/parsers/ntriples.py", line 222, in predicate
    pred = self.uriref()
  File "/usr/local/lib/python2.7/dist-packages/rdflib-4.2.2-py2.7.egg/rdflib/plugins/parsers/ntriples.py", line 238, in uriref
    return URI(uri)
  File "/usr/local/lib/python2.7/dist-packages/rdflib-4.2.2-py2.7.egg/rdflib/term.py", line 224, in __new__
    logger.warning('%s does not look like a valid URI, trying to serialize this will break.'%value)
  File "/usr/lib/python2.7/logging/__init__.py", line 1164, in warning
    self._log(WARNING, msg, args, **kwargs)
  File "/usr/lib/python2.7/logging/__init__.py", line 1271, in _log
    self.handle(record)
  File "/usr/lib/python2.7/logging/__init__.py", line 1281, in handle
    self.callHandlers(record)
  File "/usr/lib/python2.7/logging/__init__.py", line 1328, in callHandlers
    " \"%s\"\n" % self.name)
IOError: [Errno 5] Input/output error

Error: Triple:810825
Traceback (most recent call last):
  File "getResources.py", line 165, in processTriple
    g.parse(data=line,format="nquads")
  File "/usr/local/lib/python2.7/dist-packages/rdflib-4.2.2-py2.7.egg/rdflib/graph.py", line 1492, in parse
    context.parse(source, publicID=publicID, format=format, **args)
  File "/usr/local/lib/python2.7/dist-packages/rdflib-4.2.2-py2.7.egg/rdflib/graph.py", line 1039, in parse
    parser.parse(source, self, **args)
  File "/usr/local/lib/python2.7/dist-packages/rdflib-4.2.2-py2.7.egg/rdflib/plugins/parsers/nquads.py", line 64, in parse
    self.parseline()
  File "/usr/local/lib/python2.7/dist-packages/rdflib-4.2.2-py2.7.egg/rdflib/plugins/parsers/nquads.py", line 78, in parseline
    predicate = self.predicate()
  File "/usr/local/lib/python2.7/dist-packages/rdflib-4.2.2-py2.7.egg/rdflib/plugins/parsers/ntriples.py", line 222, in predicate
    pred = self.uriref()
  File "/usr/local/lib/python2.7/dist-packages/rdflib-4.2.2-py2.7.egg/rdflib/plugins/parsers/ntriples.py", line 238, in uriref
    return URI(uri)
  File "/usr/local/lib/python2.7/dist-packages/rdflib-4.2.2-py2.7.egg/rdflib/term.py", line 224, in __new__
    logger.warning('%s does not look like a valid URI, trying to serialize this will break.'%value)
  File "/usr/lib/python2.7/logging/__init__.py", line 1164, in warning
    self._log(WARNING, msg, args, **kwargs)
  File "/usr/lib/python2.7/logging/__init__.py", line 1271, in _log
    self.handle(record)
  File "/usr/lib/python2.7/logging/__init__.py", line 1281, in handle
    self.callHandlers(record)
  File "/usr/lib/python2.7/logging/__init__.py", line 1328, in callHandlers
    " \"%s\"\n" % self.name)
IOError: [Errno 5] Input/output error

Error: Triple:810825
Traceback (most recent call last):
  File "getResources.py", line 165, in processTriple
    g.parse(data=line,format="nquads")
  File "/usr/local/lib/python2.7/dist-packages/rdflib-4.2.2-py2.7.egg/rdflib/graph.py", line 1492, in parse
    context.parse(source, publicID=publicID, format=format, **args)
  File "/usr/local/lib/python2.7/dist-packages/rdflib-4.2.2-py2.7.egg/rdflib/graph.py", line 1039, in parse
    parser.parse(source, self, **args)
  File "/usr/local/lib/python2.7/dist-packages/rdflib-4.2.2-py2.7.egg/rdflib/plugins/parsers/nquads.py", line 64, in parse
    self.parseline()
  File "/usr/local/lib/python2.7/dist-packages/rdflib-4.2.2-py2.7.egg/rdflib/plugins/parsers/nquads.py", line 78, in parseline
    predicate = self.predicate()
  File "/usr/local/lib/python2.7/dist-packages/rdflib-4.2.2-py2.7.egg/rdflib/plugins/parsers/ntriples.py", line 222, in predicate
    pred = self.uriref()
  File "/usr/local/lib/python2.7/dist-packages/rdflib-4.2.2-py2.7.egg/rdflib/plugins/parsers/ntriples.py", line 238, in uriref
    return URI(uri)
  File "/usr/local/lib/python2.7/dist-packages/rdflib-4.2.2-py2.7.egg/rdflib/term.py", line 224, in __new__
    logger.warning('%s does not look like a valid URI, trying to serialize this will break.'%value)
  File "/usr/lib/python2.7/logging/__init__.py", line 1164, in warning
    self._log(WARNING, msg, args, **kwargs)
  File "/usr/lib/python2.7/logging/__init__.py", line 1271, in _log
    self.handle(record)
  File "/usr/lib/python2.7/logging/__init__.py", line 1281, in handle
    self.callHandlers(record)
  File "/usr/lib/python2.7/logging/__init__.py", line 1328, in callHandlers
    " \"%s\"\n" % self.name)
IOError: [Errno 5] Input/output error

Error: Triple:810825
Traceback (most recent call last):
  File "getResources.py", line 165, in processTriple
    g.parse(data=line,format="nquads")
  File "/usr/local/lib/python2.7/dist-packages/rdflib-4.2.2-py2.7.egg/rdflib/graph.py", line 1492, in parse
    context.parse(source, publicID=publicID, format=format, **args)
  File "/usr/local/lib/python2.7/dist-packages/rdflib-4.2.2-py2.7.egg/rdflib/graph.py", line 1039, in parse
    parser.parse(source, self, **args)
  File "/usr/local/lib/python2.7/dist-packages/rdflib-4.2.2-py2.7.egg/rdflib/plugins/parsers/nquads.py", line 64, in parse
    self.parseline()
  File "/usr/local/lib/python2.7/dist-packages/rdflib-4.2.2-py2.7.egg/rdflib/plugins/parsers/nquads.py", line 78, in parseline
    predicate = self.predicate()
  File "/usr/local/lib/python2.7/dist-packages/rdflib-4.2.2-py2.7.egg/rdflib/plugins/parsers/ntriples.py", line 222, in predicate
    pred = self.uriref()
  File "/usr/local/lib/python2.7/dist-packages/rdflib-4.2.2-py2.7.egg/rdflib/plugins/parsers/ntriples.py", line 238, in uriref
    return URI(uri)
  File "/usr/local/lib/python2.7/dist-packages/rdflib-4.2.2-py2.7.egg/rdflib/term.py", line 224, in __new__
    logger.warning('%s does not look like a valid URI, trying to serialize this will break.'%value)
  File "/usr/lib/python2.7/logging/__init__.py", line 1164, in warning
    self._log(WARNING, msg, args, **kwargs)
  File "/usr/lib/python2.7/logging/__init__.py", line 1271, in _log
    self.handle(record)
  File "/usr/lib/python2.7/logging/__init__.py", line 1281, in handle
    self.callHandlers(record)
  File "/usr/lib/python2.7/logging/__init__.py", line 1328, in callHandlers
    " \"%s\"\n" % self.name)
IOError: [Errno 5] Input/output error

Error: Triple:810825
Traceback (most recent call last):
  File "getResources.py", line 165, in processTriple
    g.parse(data=line,format="nquads")
  File "/usr/local/lib/python2.7/dist-packages/rdflib-4.2.2-py2.7.egg/rdflib/graph.py", line 1492, in parse
    context.parse(source, publicID=publicID, format=format, **args)
  File "/usr/local/lib/python2.7/dist-packages/rdflib-4.2.2-py2.7.egg/rdflib/graph.py", line 1039, in parse
    parser.parse(source, self, **args)
  File "/usr/local/lib/python2.7/dist-packages/rdflib-4.2.2-py2.7.egg/rdflib/plugins/parsers/nquads.py", line 64, in parse
    self.parseline()
  File "/usr/local/lib/python2.7/dist-packages/rdflib-4.2.2-py2.7.egg/rdflib/plugins/parsers/nquads.py", line 78, in parseline
    predicate = self.predicate()
  File "/usr/local/lib/python2.7/dist-packages/rdflib-4.2.2-py2.7.egg/rdflib/plugins/parsers/ntriples.py", line 222, in predicate
    pred = self.uriref()
  File "/usr/local/lib/python2.7/dist-packages/rdflib-4.2.2-py2.7.egg/rdflib/plugins/parsers/ntriples.py", line 238, in uriref
    return URI(uri)
  File "/usr/local/lib/python2.7/dist-packages/rdflib-4.2.2-py2.7.egg/rdflib/term.py", line 224, in __new__
    logger.warning('%s does not look like a valid URI, trying to serialize this will break.'%value)
  File "/usr/lib/python2.7/logging/__init__.py", line 1164, in warning
    self._log(WARNING, msg, args, **kwargs)
  File "/usr/lib/python2.7/logging/__init__.py", line 1271, in _log
    self.handle(record)
  File "/usr/lib/python2.7/logging/__init__.py", line 1281, in handle
    self.callHandlers(record)
  File "/usr/lib/python2.7/logging/__init__.py", line 1328, in callHandlers
    " \"%s\"\n" % self.name)
IOError: [Errno 5] Input/output error

Error: Triple:810827
Traceback (most recent call last):
  File "getResources.py", line 165, in processTriple
    g.parse(data=line,format="nquads")
  File "/usr/local/lib/python2.7/dist-packages/rdflib-4.2.2-py2.7.egg/rdflib/graph.py", line 1492, in parse
    context.parse(source, publicID=publicID, format=format, **args)
  File "/usr/local/lib/python2.7/dist-packages/rdflib-4.2.2-py2.7.egg/rdflib/graph.py", line 1039, in parse
    parser.parse(source, self, **args)
  File "/usr/local/lib/python2.7/dist-packages/rdflib-4.2.2-py2.7.egg/rdflib/plugins/parsers/nquads.py", line 64, in parse
    self.parseline()
  File "/usr/local/lib/python2.7/dist-packages/rdflib-4.2.2-py2.7.egg/rdflib/plugins/parsers/nquads.py", line 78, in parseline
    predicate = self.predicate()
  File "/usr/local/lib/python2.7/dist-packages/rdflib-4.2.2-py2.7.egg/rdflib/plugins/parsers/ntriples.py", line 222, in predicate
    pred = self.uriref()
  File "/usr/local/lib/python2.7/dist-packages/rdflib-4.2.2-py2.7.egg/rdflib/plugins/parsers/ntriples.py", line 238, in uriref
    return URI(uri)
  File "/usr/local/lib/python2.7/dist-packages/rdflib-4.2.2-py2.7.egg/rdflib/term.py", line 224, in __new__
    logger.warning('%s does not look like a valid URI, trying to serialize this will break.'%value)
  File "/usr/lib/python2.7/logging/__init__.py", line 1164, in warning
    self._log(WARNING, msg, args, **kwargs)
  File "/usr/lib/python2.7/logging/__init__.py", line 1271, in _log
    self.handle(record)
  File "/usr/lib/python2.7/logging/__init__.py", line 1281, in handle
    self.callHandlers(record)
  File "/usr/lib/python2.7/logging/__init__.py", line 1328, in callHandlers
    " \"%s\"\n" % self.name)
IOError: [Errno 5] Input/output error

Error: Triple:810827
Traceback (most recent call last):
  File "getResources.py", line 165, in processTriple
    g.parse(data=line,format="nquads")
  File "/usr/local/lib/python2.7/dist-packages/rdflib-4.2.2-py2.7.egg/rdflib/graph.py", line 1492, in parse
    context.parse(source, publicID=publicID, format=format, **args)
  File "/usr/local/lib/python2.7/dist-packages/rdflib-4.2.2-py2.7.egg/rdflib/graph.py", line 1039, in parse
    parser.parse(source, self, **args)
  File "/usr/local/lib/python2.7/dist-packages/rdflib-4.2.2-py2.7.egg/rdflib/plugins/parsers/nquads.py", line 64, in parse
    self.parseline()
  File "/usr/local/lib/python2.7/dist-packages/rdflib-4.2.2-py2.7.egg/rdflib/plugins/parsers/nquads.py", line 78, in parseline
    predicate = self.predicate()
  File "/usr/local/lib/python2.7/dist-packages/rdflib-4.2.2-py2.7.egg/rdflib/plugins/parsers/ntriples.py", line 222, in predicate
    pred = self.uriref()
  File "/usr/local/lib/python2.7/dist-packages/rdflib-4.2.2-py2.7.egg/rdflib/plugins/parsers/ntriples.py", line 238, in uriref
    return URI(uri)
  File "/usr/local/lib/python2.7/dist-packages/rdflib-4.2.2-py2.7.egg/rdflib/term.py", line 224, in __new__
    logger.warning('%s does not look like a valid URI, trying to serialize this will break.'%value)
  File "/usr/lib/python2.7/logging/__init__.py", line 1164, in warning
    self._log(WARNING, msg, args, **kwargs)
  File "/usr/lib/python2.7/logging/__init__.py", line 1271, in _log
    self.handle(record)
  File "/usr/lib/python2.7/logging/__init__.py", line 1281, in handle
    self.callHandlers(record)
  File "/usr/lib/python2.7/logging/__init__.py", line 1328, in callHandlers
    " \"%s\"\n" % self.name)
IOError: [Errno 5] Input/output error

Error: Triple:810827
Traceback (most recent call last):
  File "getResources.py", line 165, in processTriple
    g.parse(data=line,format="nquads")
  File "/usr/local/lib/python2.7/dist-packages/rdflib-4.2.2-py2.7.egg/rdflib/graph.py", line 1492, in parse
    context.parse(source, publicID=publicID, format=format, **args)
  File "/usr/local/lib/python2.7/dist-packages/rdflib-4.2.2-py2.7.egg/rdflib/graph.py", line 1039, in parse
    parser.parse(source, self, **args)
  File "/usr/local/lib/python2.7/dist-packages/rdflib-4.2.2-py2.7.egg/rdflib/plugins/parsers/nquads.py", line 64, in parse
    self.parseline()
  File "/usr/local/lib/python2.7/dist-packages/rdflib-4.2.2-py2.7.egg/rdflib/plugins/parsers/nquads.py", line 78, in parseline
    predicate = self.predicate()
  File "/usr/local/lib/python2.7/dist-packages/rdflib-4.2.2-py2.7.egg/rdflib/plugins/parsers/ntriples.py", line 222, in predicate
    pred = self.uriref()
  File "/usr/local/lib/python2.7/dist-packages/rdflib-4.2.2-py2.7.egg/rdflib/plugins/parsers/ntriples.py", line 238, in uriref
    return URI(uri)
  File "/usr/local/lib/python2.7/dist-packages/rdflib-4.2.2-py2.7.egg/rdflib/term.py", line 224, in __new__
    logger.warning('%s does not look like a valid URI, trying to serialize this will break.'%value)
  File "/usr/lib/python2.7/logging/__init__.py", line 1164, in warning
    self._log(WARNING, msg, args, **kwargs)
  File "/usr/lib/python2.7/logging/__init__.py", line 1271, in _log
    self.handle(record)
  File "/usr/lib/python2.7/logging/__init__.py", line 1281, in handle
    self.callHandlers(record)
  File "/usr/lib/python2.7/logging/__init__.py", line 1328, in callHandlers
    " \"%s\"\n" % self.name)
IOError: [Errno 5] Input/output error

Error: Triple:810827
Traceback (most recent call last):
  File "getResources.py", line 165, in processTriple
    g.parse(data=line,format="nquads")
  File "/usr/local/lib/python2.7/dist-packages/rdflib-4.2.2-py2.7.egg/rdflib/graph.py", line 1492, in parse
    context.parse(source, publicID=publicID, format=format, **args)
  File "/usr/local/lib/python2.7/dist-packages/rdflib-4.2.2-py2.7.egg/rdflib/graph.py", line 1039, in parse
    parser.parse(source, self, **args)
  File "/usr/local/lib/python2.7/dist-packages/rdflib-4.2.2-py2.7.egg/rdflib/plugins/parsers/nquads.py", line 64, in parse
    self.parseline()
  File "/usr/local/lib/python2.7/dist-packages/rdflib-4.2.2-py2.7.egg/rdflib/plugins/parsers/nquads.py", line 78, in parseline
    predicate = self.predicate()
  File "/usr/local/lib/python2.7/dist-packages/rdflib-4.2.2-py2.7.egg/rdflib/plugins/parsers/ntriples.py", line 222, in predicate
    pred = self.uriref()
  File "/usr/local/lib/python2.7/dist-packages/rdflib-4.2.2-py2.7.egg/rdflib/plugins/parsers/ntriples.py", line 238, in uriref
    return URI(uri)
  File "/usr/local/lib/python2.7/dist-packages/rdflib-4.2.2-py2.7.egg/rdflib/term.py", line 224, in __new__
    logger.warning('%s does not look like a valid URI, trying to serialize this will break.'%value)
  File "/usr/lib/python2.7/logging/__init__.py", line 1164, in warning
    self._log(WARNING, msg, args, **kwargs)
  File "/usr/lib/python2.7/logging/__init__.py", line 1271, in _log
    self.handle(record)
  File "/usr/lib/python2.7/logging/__init__.py", line 1281, in handle
    self.callHandlers(record)
  File "/usr/lib/python2.7/logging/__init__.py", line 1328, in callHandlers
    " \"%s\"\n" % self.name)
IOError: [Errno 5] Input/output error

Error: Triple:810829
Traceback (most recent call last):
  File "getResources.py", line 165, in processTriple
    g.parse(data=line,format="nquads")
  File "/usr/local/lib/python2.7/dist-packages/rdflib-4.2.2-py2.7.egg/rdflib/graph.py", line 1492, in parse
    context.parse(source, publicID=publicID, format=format, **args)
  File "/usr/local/lib/python2.7/dist-packages/rdflib-4.2.2-py2.7.egg/rdflib/graph.py", line 1039, in parse
    parser.parse(source, self, **args)
  File "/usr/local/lib/python2.7/dist-packages/rdflib-4.2.2-py2.7.egg/rdflib/plugins/parsers/nquads.py", line 64, in parse
    self.parseline()
  File "/usr/local/lib/python2.7/dist-packages/rdflib-4.2.2-py2.7.egg/rdflib/plugins/parsers/nquads.py", line 78, in parseline
    predicate = self.predicate()
  File "/usr/local/lib/python2.7/dist-packages/rdflib-4.2.2-py2.7.egg/rdflib/plugins/parsers/ntriples.py", line 222, in predicate
    pred = self.uriref()
  File "/usr/local/lib/python2.7/dist-packages/rdflib-4.2.2-py2.7.egg/rdflib/plugins/parsers/ntriples.py", line 238, in uriref
    return URI(uri)
  File "/usr/local/lib/python2.7/dist-packages/rdflib-4.2.2-py2.7.egg/rdflib/term.py", line 224, in __new__
    logger.warning('%s does not look like a valid URI, trying to serialize this will break.'%value)
  File "/usr/lib/python2.7/logging/__init__.py", line 1164, in warning
    self._log(WARNING, msg, args, **kwargs)
  File "/usr/lib/python2.7/logging/__init__.py", line 1271, in _log
    self.handle(record)
  File "/usr/lib/python2.7/logging/__init__.py", line 1281, in handle
    self.callHandlers(record)
  File "/usr/lib/python2.7/logging/__init__.py", line 1328, in callHandlers
    " \"%s\"\n" % self.name)
IOError: [Errno 5] Input/output error

Error: Triple:810829
Traceback (most recent call last):
  File "getResources.py", line 165, in processTriple
    g.parse(data=line,format="nquads")
  File "/usr/local/lib/python2.7/dist-packages/rdflib-4.2.2-py2.7.egg/rdflib/graph.py", line 1492, in parse
    context.parse(source, publicID=publicID, format=format, **args)
  File "/usr/local/lib/python2.7/dist-packages/rdflib-4.2.2-py2.7.egg/rdflib/graph.py", line 1039, in parse
    parser.parse(source, self, **args)
  File "/usr/local/lib/python2.7/dist-packages/rdflib-4.2.2-py2.7.egg/rdflib/plugins/parsers/nquads.py", line 64, in parse
    self.parseline()
  File "/usr/local/lib/python2.7/dist-packages/rdflib-4.2.2-py2.7.egg/rdflib/plugins/parsers/nquads.py", line 78, in parseline
    predicate = self.predicate()
  File "/usr/local/lib/python2.7/dist-packages/rdflib-4.2.2-py2.7.egg/rdflib/plugins/parsers/ntriples.py", line 222, in predicate
    pred = self.uriref()
  File "/usr/local/lib/python2.7/dist-packages/rdflib-4.2.2-py2.7.egg/rdflib/plugins/parsers/ntriples.py", line 238, in uriref
    return URI(uri)
  File "/usr/local/lib/python2.7/dist-packages/rdflib-4.2.2-py2.7.egg/rdflib/term.py", line 224, in __new__
    logger.warning('%s does not look like a valid URI, trying to serialize this will break.'%value)
  File "/usr/lib/python2.7/logging/__init__.py", line 1164, in warning
    self._log(WARNING, msg, args, **kwargs)
  File "/usr/lib/python2.7/logging/__init__.py", line 1271, in _log
    self.handle(record)
  File "/usr/lib/python2.7/logging/__init__.py", line 1281, in handle
    self.callHandlers(record)
  File "/usr/lib/python2.7/logging/__init__.py", line 1328, in callHandlers
    " \"%s\"\n" % self.name)
IOError: [Errno 5] Input/output error

Error: Triple:810829
Traceback (most recent call last):
  File "getResources.py", line 165, in processTriple
    g.parse(data=line,format="nquads")
  File "/usr/local/lib/python2.7/dist-packages/rdflib-4.2.2-py2.7.egg/rdflib/graph.py", line 1492, in parse
    context.parse(source, publicID=publicID, format=format, **args)
  File "/usr/local/lib/python2.7/dist-packages/rdflib-4.2.2-py2.7.egg/rdflib/graph.py", line 1039, in parse
    parser.parse(source, self, **args)
  File "/usr/local/lib/python2.7/dist-packages/rdflib-4.2.2-py2.7.egg/rdflib/plugins/parsers/nquads.py", line 64, in parse
    self.parseline()
  File "/usr/local/lib/python2.7/dist-packages/rdflib-4.2.2-py2.7.egg/rdflib/plugins/parsers/nquads.py", line 78, in parseline
    predicate = self.predicate()
  File "/usr/local/lib/python2.7/dist-packages/rdflib-4.2.2-py2.7.egg/rdflib/plugins/parsers/ntriples.py", line 222, in predicate
    pred = self.uriref()
  File "/usr/local/lib/python2.7/dist-packages/rdflib-4.2.2-py2.7.egg/rdflib/plugins/parsers/ntriples.py", line 238, in uriref
    return URI(uri)
  File "/usr/local/lib/python2.7/dist-packages/rdflib-4.2.2-py2.7.egg/rdflib/term.py", line 224, in __new__
    logger.warning('%s does not look like a valid URI, trying to serialize this will break.'%value)
  File "/usr/lib/python2.7/logging/__init__.py", line 1164, in warning
    self._log(WARNING, msg, args, **kwargs)
  File "/usr/lib/python2.7/logging/__init__.py", line 1271, in _log
    self.handle(record)
  File "/usr/lib/python2.7/logging/__init__.py", line 1281, in handle
    self.callHandlers(record)
  File "/usr/lib/python2.7/logging/__init__.py", line 1328, in callHandlers
    " \"%s\"\n" % self.name)
IOError: [Errno 5] Input/output error

Error: Triple:810829
Traceback (most recent call last):
  File "getResources.py", line 165, in processTriple
    g.parse(data=line,format="nquads")
  File "/usr/local/lib/python2.7/dist-packages/rdflib-4.2.2-py2.7.egg/rdflib/graph.py", line 1492, in parse
    context.parse(source, publicID=publicID, format=format, **args)
  File "/usr/local/lib/python2.7/dist-packages/rdflib-4.2.2-py2.7.egg/rdflib/graph.py", line 1039, in parse
    parser.parse(source, self, **args)
  File "/usr/local/lib/python2.7/dist-packages/rdflib-4.2.2-py2.7.egg/rdflib/plugins/parsers/nquads.py", line 64, in parse
    self.parseline()
  File "/usr/local/lib/python2.7/dist-packages/rdflib-4.2.2-py2.7.egg/rdflib/plugins/parsers/nquads.py", line 78, in parseline
    predicate = self.predicate()
  File "/usr/local/lib/python2.7/dist-packages/rdflib-4.2.2-py2.7.egg/rdflib/plugins/parsers/ntriples.py", line 222, in predicate
    pred = self.uriref()
  File "/usr/local/lib/python2.7/dist-packages/rdflib-4.2.2-py2.7.egg/rdflib/plugins/parsers/ntriples.py", line 238, in uriref
    return URI(uri)
  File "/usr/local/lib/python2.7/dist-packages/rdflib-4.2.2-py2.7.egg/rdflib/term.py", line 224, in __new__
    logger.warning('%s does not look like a valid URI, trying to serialize this will break.'%value)
  File "/usr/lib/python2.7/logging/__init__.py", line 1164, in warning
    self._log(WARNING, msg, args, **kwargs)
  File "/usr/lib/python2.7/logging/__init__.py", line 1271, in _log
    self.handle(record)
  File "/usr/lib/python2.7/logging/__init__.py", line 1281, in handle
    self.callHandlers(record)
  File "/usr/lib/python2.7/logging/__init__.py", line 1328, in callHandlers
    " \"%s\"\n" % self.name)
IOError: [Errno 5] Input/output error

Error: Triple:810829
Traceback (most recent call last):
  File "getResources.py", line 165, in processTriple
    g.parse(data=line,format="nquads")
  File "/usr/local/lib/python2.7/dist-packages/rdflib-4.2.2-py2.7.egg/rdflib/graph.py", line 1492, in parse
    context.parse(source, publicID=publicID, format=format, **args)
  File "/usr/local/lib/python2.7/dist-packages/rdflib-4.2.2-py2.7.egg/rdflib/graph.py", line 1039, in parse
    parser.parse(source, self, **args)
  File "/usr/local/lib/python2.7/dist-packages/rdflib-4.2.2-py2.7.egg/rdflib/plugins/parsers/nquads.py", line 64, in parse
    self.parseline()
  File "/usr/local/lib/python2.7/dist-packages/rdflib-4.2.2-py2.7.egg/rdflib/plugins/parsers/nquads.py", line 78, in parseline
    predicate = self.predicate()
  File "/usr/local/lib/python2.7/dist-packages/rdflib-4.2.2-py2.7.egg/rdflib/plugins/parsers/ntriples.py", line 222, in predicate
    pred = self.uriref()
  File "/usr/local/lib/python2.7/dist-packages/rdflib-4.2.2-py2.7.egg/rdflib/plugins/parsers/ntriples.py", line 238, in uriref
    return URI(uri)
  File "/usr/local/lib/python2.7/dist-packages/rdflib-4.2.2-py2.7.egg/rdflib/term.py", line 224, in __new__
    logger.warning('%s does not look like a valid URI, trying to serialize this will break.'%value)
  File "/usr/lib/python2.7/logging/__init__.py", line 1164, in warning
    self._log(WARNING, msg, args, **kwargs)
  File "/usr/lib/python2.7/logging/__init__.py", line 1271, in _log
    self.handle(record)
  File "/usr/lib/python2.7/logging/__init__.py", line 1281, in handle
    self.callHandlers(record)
  File "/usr/lib/python2.7/logging/__init__.py", line 1328, in callHandlers
    " \"%s\"\n" % self.name)
IOError: [Errno 5] Input/output error

Error: Triple:810830
Traceback (most recent call last):
  File "getResources.py", line 165, in processTriple
    g.parse(data=line,format="nquads")
  File "/usr/local/lib/python2.7/dist-packages/rdflib-4.2.2-py2.7.egg/rdflib/graph.py", line 1492, in parse
    context.parse(source, publicID=publicID, format=format, **args)
  File "/usr/local/lib/python2.7/dist-packages/rdflib-4.2.2-py2.7.egg/rdflib/graph.py", line 1039, in parse
    parser.parse(source, self, **args)
  File "/usr/local/lib/python2.7/dist-packages/rdflib-4.2.2-py2.7.egg/rdflib/plugins/parsers/nquads.py", line 64, in parse
    self.parseline()
  File "/usr/local/lib/python2.7/dist-packages/rdflib-4.2.2-py2.7.egg/rdflib/plugins/parsers/nquads.py", line 78, in parseline
    predicate = self.predicate()
  File "/usr/local/lib/python2.7/dist-packages/rdflib-4.2.2-py2.7.egg/rdflib/plugins/parsers/ntriples.py", line 222, in predicate
    pred = self.uriref()
  File "/usr/local/lib/python2.7/dist-packages/rdflib-4.2.2-py2.7.egg/rdflib/plugins/parsers/ntriples.py", line 238, in uriref
    return URI(uri)
  File "/usr/local/lib/python2.7/dist-packages/rdflib-4.2.2-py2.7.egg/rdflib/term.py", line 224, in __new__
    logger.warning('%s does not look like a valid URI, trying to serialize this will break.'%value)
  File "/usr/lib/python2.7/logging/__init__.py", line 1164, in warning
    self._log(WARNING, msg, args, **kwargs)
  File "/usr/lib/python2.7/logging/__init__.py", line 1271, in _log
    self.handle(record)
  File "/usr/lib/python2.7/logging/__init__.py", line 1281, in handle
    self.callHandlers(record)
  File "/usr/lib/python2.7/logging/__init__.py", line 1328, in callHandlers
    " \"%s\"\n" % self.name)
IOError: [Errno 5] Input/output error

Error: Triple:810833
Traceback (most recent call last):
  File "getResources.py", line 165, in processTriple
    g.parse(data=line,format="nquads")
  File "/usr/local/lib/python2.7/dist-packages/rdflib-4.2.2-py2.7.egg/rdflib/graph.py", line 1492, in parse
    context.parse(source, publicID=publicID, format=format, **args)
  File "/usr/local/lib/python2.7/dist-packages/rdflib-4.2.2-py2.7.egg/rdflib/graph.py", line 1039, in parse
    parser.parse(source, self, **args)
  File "/usr/local/lib/python2.7/dist-packages/rdflib-4.2.2-py2.7.egg/rdflib/plugins/parsers/nquads.py", line 64, in parse
    self.parseline()
  File "/usr/local/lib/python2.7/dist-packages/rdflib-4.2.2-py2.7.egg/rdflib/plugins/parsers/nquads.py", line 78, in parseline
    predicate = self.predicate()
  File "/usr/local/lib/python2.7/dist-packages/rdflib-4.2.2-py2.7.egg/rdflib/plugins/parsers/ntriples.py", line 222, in predicate
    pred = self.uriref()
  File "/usr/local/lib/python2.7/dist-packages/rdflib-4.2.2-py2.7.egg/rdflib/plugins/parsers/ntriples.py", line 238, in uriref
    return URI(uri)
  File "/usr/local/lib/python2.7/dist-packages/rdflib-4.2.2-py2.7.egg/rdflib/term.py", line 224, in __new__
    logger.warning('%s does not look like a valid URI, trying to serialize this will break.'%value)
  File "/usr/lib/python2.7/logging/__init__.py", line 1164, in warning
    self._log(WARNING, msg, args, **kwargs)
  File "/usr/lib/python2.7/logging/__init__.py", line 1271, in _log
    self.handle(record)
  File "/usr/lib/python2.7/logging/__init__.py", line 1281, in handle
    self.callHandlers(record)
  File "/usr/lib/python2.7/logging/__init__.py", line 1328, in callHandlers
    " \"%s\"\n" % self.name)
IOError: [Errno 5] Input/output error

Error: Triple:810833
Traceback (most recent call last):
  File "getResources.py", line 165, in processTriple
    g.parse(data=line,format="nquads")
  File "/usr/local/lib/python2.7/dist-packages/rdflib-4.2.2-py2.7.egg/rdflib/graph.py", line 1492, in parse
    context.parse(source, publicID=publicID, format=format, **args)
  File "/usr/local/lib/python2.7/dist-packages/rdflib-4.2.2-py2.7.egg/rdflib/graph.py", line 1039, in parse
    parser.parse(source, self, **args)
  File "/usr/local/lib/python2.7/dist-packages/rdflib-4.2.2-py2.7.egg/rdflib/plugins/parsers/nquads.py", line 64, in parse
    self.parseline()
  File "/usr/local/lib/python2.7/dist-packages/rdflib-4.2.2-py2.7.egg/rdflib/plugins/parsers/nquads.py", line 78, in parseline
    predicate = self.predicate()
  File "/usr/local/lib/python2.7/dist-packages/rdflib-4.2.2-py2.7.egg/rdflib/plugins/parsers/ntriples.py", line 222, in predicate
    pred = self.uriref()
  File "/usr/local/lib/python2.7/dist-packages/rdflib-4.2.2-py2.7.egg/rdflib/plugins/parsers/ntriples.py", line 238, in uriref
    return URI(uri)
  File "/usr/local/lib/python2.7/dist-packages/rdflib-4.2.2-py2.7.egg/rdflib/term.py", line 224, in __new__
    logger.warning('%s does not look like a valid URI, trying to serialize this will break.'%value)
  File "/usr/lib/python2.7/logging/__init__.py", line 1164, in warning
    self._log(WARNING, msg, args, **kwargs)
  File "/usr/lib/python2.7/logging/__init__.py", line 1271, in _log
    self.handle(record)
  File "/usr/lib/python2.7/logging/__init__.py", line 1281, in handle
    self.callHandlers(record)
  File "/usr/lib/python2.7/logging/__init__.py", line 1328, in callHandlers
    " \"%s\"\n" % self.name)
IOError: [Errno 5] Input/output error

Error: Triple:810833
Traceback (most recent call last):
  File "getResources.py", line 165, in processTriple
    g.parse(data=line,format="nquads")
  File "/usr/local/lib/python2.7/dist-packages/rdflib-4.2.2-py2.7.egg/rdflib/graph.py", line 1492, in parse
    context.parse(source, publicID=publicID, format=format, **args)
  File "/usr/local/lib/python2.7/dist-packages/rdflib-4.2.2-py2.7.egg/rdflib/graph.py", line 1039, in parse
    parser.parse(source, self, **args)
  File "/usr/local/lib/python2.7/dist-packages/rdflib-4.2.2-py2.7.egg/rdflib/plugins/parsers/nquads.py", line 64, in parse
    self.parseline()
  File "/usr/local/lib/python2.7/dist-packages/rdflib-4.2.2-py2.7.egg/rdflib/plugins/parsers/nquads.py", line 78, in parseline
    predicate = self.predicate()
  File "/usr/local/lib/python2.7/dist-packages/rdflib-4.2.2-py2.7.egg/rdflib/plugins/parsers/ntriples.py", line 222, in predicate
    pred = self.uriref()
  File "/usr/local/lib/python2.7/dist-packages/rdflib-4.2.2-py2.7.egg/rdflib/plugins/parsers/ntriples.py", line 238, in uriref
    return URI(uri)
  File "/usr/local/lib/python2.7/dist-packages/rdflib-4.2.2-py2.7.egg/rdflib/term.py", line 224, in __new__
    logger.warning('%s does not look like a valid URI, trying to serialize this will break.'%value)
  File "/usr/lib/python2.7/logging/__init__.py", line 1164, in warning
    self._log(WARNING, msg, args, **kwargs)
  File "/usr/lib/python2.7/logging/__init__.py", line 1271, in _log
    self.handle(record)
  File "/usr/lib/python2.7/logging/__init__.py", line 1281, in handle
    self.callHandlers(record)
  File "/usr/lib/python2.7/logging/__init__.py", line 1328, in callHandlers
    " \"%s\"\n" % self.name)
IOError: [Errno 5] Input/output error

Error: Triple:810833
Traceback (most recent call last):
  File "getResources.py", line 165, in processTriple
    g.parse(data=line,format="nquads")
  File "/usr/local/lib/python2.7/dist-packages/rdflib-4.2.2-py2.7.egg/rdflib/graph.py", line 1492, in parse
    context.parse(source, publicID=publicID, format=format, **args)
  File "/usr/local/lib/python2.7/dist-packages/rdflib-4.2.2-py2.7.egg/rdflib/graph.py", line 1039, in parse
    parser.parse(source, self, **args)
  File "/usr/local/lib/python2.7/dist-packages/rdflib-4.2.2-py2.7.egg/rdflib/plugins/parsers/nquads.py", line 64, in parse
    self.parseline()
  File "/usr/local/lib/python2.7/dist-packages/rdflib-4.2.2-py2.7.egg/rdflib/plugins/parsers/nquads.py", line 78, in parseline
    predicate = self.predicate()
  File "/usr/local/lib/python2.7/dist-packages/rdflib-4.2.2-py2.7.egg/rdflib/plugins/parsers/ntriples.py", line 222, in predicate
    pred = self.uriref()
  File "/usr/local/lib/python2.7/dist-packages/rdflib-4.2.2-py2.7.egg/rdflib/plugins/parsers/ntriples.py", line 238, in uriref
    return URI(uri)
  File "/usr/local/lib/python2.7/dist-packages/rdflib-4.2.2-py2.7.egg/rdflib/term.py", line 224, in __new__
    logger.warning('%s does not look like a valid URI, trying to serialize this will break.'%value)
  File "/usr/lib/python2.7/logging/__init__.py", line 1164, in warning
    self._log(WARNING, msg, args, **kwargs)
  File "/usr/lib/python2.7/logging/__init__.py", line 1271, in _log
    self.handle(record)
  File "/usr/lib/python2.7/logging/__init__.py", line 1281, in handle
    self.callHandlers(record)
  File "/usr/lib/python2.7/logging/__init__.py", line 1328, in callHandlers
    " \"%s\"\n" % self.name)
IOError: [Errno 5] Input/output error

Error: Triple:810833
Traceback (most recent call last):
  File "getResources.py", line 165, in processTriple
    g.parse(data=line,format="nquads")
  File "/usr/local/lib/python2.7/dist-packages/rdflib-4.2.2-py2.7.egg/rdflib/graph.py", line 1492, in parse
    context.parse(source, publicID=publicID, format=format, **args)
  File "/usr/local/lib/python2.7/dist-packages/rdflib-4.2.2-py2.7.egg/rdflib/graph.py", line 1039, in parse
    parser.parse(source, self, **args)
  File "/usr/local/lib/python2.7/dist-packages/rdflib-4.2.2-py2.7.egg/rdflib/plugins/parsers/nquads.py", line 64, in parse
    self.parseline()
  File "/usr/local/lib/python2.7/dist-packages/rdflib-4.2.2-py2.7.egg/rdflib/plugins/parsers/nquads.py", line 78, in parseline
    predicate = self.predicate()
  File "/usr/local/lib/python2.7/dist-packages/rdflib-4.2.2-py2.7.egg/rdflib/plugins/parsers/ntriples.py", line 222, in predicate
    pred = self.uriref()
  File "/usr/local/lib/python2.7/dist-packages/rdflib-4.2.2-py2.7.egg/rdflib/plugins/parsers/ntriples.py", line 238, in uriref
    return URI(uri)
  File "/usr/local/lib/python2.7/dist-packages/rdflib-4.2.2-py2.7.egg/rdflib/term.py", line 224, in __new__
    logger.warning('%s does not look like a valid URI, trying to serialize this will break.'%value)
  File "/usr/lib/python2.7/logging/__init__.py", line 1164, in warning
    self._log(WARNING, msg, args, **kwargs)
  File "/usr/lib/python2.7/logging/__init__.py", line 1271, in _log
    self.handle(record)
  File "/usr/lib/python2.7/logging/__init__.py", line 1281, in handle
    self.callHandlers(record)
  File "/usr/lib/python2.7/logging/__init__.py", line 1328, in callHandlers
    " \"%s\"\n" % self.name)
IOError: [Errno 5] Input/output error

Error: Triple:810835
Traceback (most recent call last):
  File "getResources.py", line 165, in processTriple
    g.parse(data=line,format="nquads")
  File "/usr/local/lib/python2.7/dist-packages/rdflib-4.2.2-py2.7.egg/rdflib/graph.py", line 1492, in parse
    context.parse(source, publicID=publicID, format=format, **args)
  File "/usr/local/lib/python2.7/dist-packages/rdflib-4.2.2-py2.7.egg/rdflib/graph.py", line 1039, in parse
    parser.parse(source, self, **args)
  File "/usr/local/lib/python2.7/dist-packages/rdflib-4.2.2-py2.7.egg/rdflib/plugins/parsers/nquads.py", line 64, in parse
    self.parseline()
  File "/usr/local/lib/python2.7/dist-packages/rdflib-4.2.2-py2.7.egg/rdflib/plugins/parsers/nquads.py", line 78, in parseline
    predicate = self.predicate()
  File "/usr/local/lib/python2.7/dist-packages/rdflib-4.2.2-py2.7.egg/rdflib/plugins/parsers/ntriples.py", line 222, in predicate
    pred = self.uriref()
  File "/usr/local/lib/python2.7/dist-packages/rdflib-4.2.2-py2.7.egg/rdflib/plugins/parsers/ntriples.py", line 238, in uriref
    return URI(uri)
  File "/usr/local/lib/python2.7/dist-packages/rdflib-4.2.2-py2.7.egg/rdflib/term.py", line 224, in __new__
    logger.warning('%s does not look like a valid URI, trying to serialize this will break.'%value)
  File "/usr/lib/python2.7/logging/__init__.py", line 1164, in warning
    self._log(WARNING, msg, args, **kwargs)
  File "/usr/lib/python2.7/logging/__init__.py", line 1271, in _log
    self.handle(record)
  File "/usr/lib/python2.7/logging/__init__.py", line 1281, in handle
    self.callHandlers(record)
  File "/usr/lib/python2.7/logging/__init__.py", line 1328, in callHandlers
    " \"%s\"\n" % self.name)
IOError: [Errno 5] Input/output error

Error: Triple:810838
Traceback (most recent call last):
  File "getResources.py", line 165, in processTriple
    g.parse(data=line,format="nquads")
  File "/usr/local/lib/python2.7/dist-packages/rdflib-4.2.2-py2.7.egg/rdflib/graph.py", line 1492, in parse
    context.parse(source, publicID=publicID, format=format, **args)
  File "/usr/local/lib/python2.7/dist-packages/rdflib-4.2.2-py2.7.egg/rdflib/graph.py", line 1039, in parse
    parser.parse(source, self, **args)
  File "/usr/local/lib/python2.7/dist-packages/rdflib-4.2.2-py2.7.egg/rdflib/plugins/parsers/nquads.py", line 64, in parse
    self.parseline()
  File "/usr/local/lib/python2.7/dist-packages/rdflib-4.2.2-py2.7.egg/rdflib/plugins/parsers/nquads.py", line 78, in parseline
    predicate = self.predicate()
  File "/usr/local/lib/python2.7/dist-packages/rdflib-4.2.2-py2.7.egg/rdflib/plugins/parsers/ntriples.py", line 222, in predicate
    pred = self.uriref()
  File "/usr/local/lib/python2.7/dist-packages/rdflib-4.2.2-py2.7.egg/rdflib/plugins/parsers/ntriples.py", line 238, in uriref
    return URI(uri)
  File "/usr/local/lib/python2.7/dist-packages/rdflib-4.2.2-py2.7.egg/rdflib/term.py", line 224, in __new__
    logger.warning('%s does not look like a valid URI, trying to serialize this will break.'%value)
  File "/usr/lib/python2.7/logging/__init__.py", line 1164, in warning
    self._log(WARNING, msg, args, **kwargs)
  File "/usr/lib/python2.7/logging/__init__.py", line 1271, in _log
    self.handle(record)
  File "/usr/lib/python2.7/logging/__init__.py", line 1281, in handle
    self.callHandlers(record)
  File "/usr/lib/python2.7/logging/__init__.py", line 1328, in callHandlers
    " \"%s\"\n" % self.name)
IOError: [Errno 5] Input/output error

Error: Triple:810838
Traceback (most recent call last):
  File "getResources.py", line 165, in processTriple
    g.parse(data=line,format="nquads")
  File "/usr/local/lib/python2.7/dist-packages/rdflib-4.2.2-py2.7.egg/rdflib/graph.py", line 1492, in parse
    context.parse(source, publicID=publicID, format=format, **args)
  File "/usr/local/lib/python2.7/dist-packages/rdflib-4.2.2-py2.7.egg/rdflib/graph.py", line 1039, in parse
    parser.parse(source, self, **args)
  File "/usr/local/lib/python2.7/dist-packages/rdflib-4.2.2-py2.7.egg/rdflib/plugins/parsers/nquads.py", line 64, in parse
    self.parseline()
  File "/usr/local/lib/python2.7/dist-packages/rdflib-4.2.2-py2.7.egg/rdflib/plugins/parsers/nquads.py", line 78, in parseline
    predicate = self.predicate()
  File "/usr/local/lib/python2.7/dist-packages/rdflib-4.2.2-py2.7.egg/rdflib/plugins/parsers/ntriples.py", line 222, in predicate
    pred = self.uriref()
  File "/usr/local/lib/python2.7/dist-packages/rdflib-4.2.2-py2.7.egg/rdflib/plugins/parsers/ntriples.py", line 238, in uriref
    return URI(uri)
  File "/usr/local/lib/python2.7/dist-packages/rdflib-4.2.2-py2.7.egg/rdflib/term.py", line 224, in __new__
    logger.warning('%s does not look like a valid URI, trying to serialize this will break.'%value)
  File "/usr/lib/python2.7/logging/__init__.py", line 1164, in warning
    self._log(WARNING, msg, args, **kwargs)
  File "/usr/lib/python2.7/logging/__init__.py", line 1271, in _log
    self.handle(record)
  File "/usr/lib/python2.7/logging/__init__.py", line 1281, in handle
    self.callHandlers(record)
  File "/usr/lib/python2.7/logging/__init__.py", line 1328, in callHandlers
    " \"%s\"\n" % self.name)
IOError: [Errno 5] Input/output error

Error: Triple:810838
Traceback (most recent call last):
  File "getResources.py", line 165, in processTriple
    g.parse(data=line,format="nquads")
  File "/usr/local/lib/python2.7/dist-packages/rdflib-4.2.2-py2.7.egg/rdflib/graph.py", line 1492, in parse
    context.parse(source, publicID=publicID, format=format, **args)
  File "/usr/local/lib/python2.7/dist-packages/rdflib-4.2.2-py2.7.egg/rdflib/graph.py", line 1039, in parse
    parser.parse(source, self, **args)
  File "/usr/local/lib/python2.7/dist-packages/rdflib-4.2.2-py2.7.egg/rdflib/plugins/parsers/nquads.py", line 64, in parse
    self.parseline()
  File "/usr/local/lib/python2.7/dist-packages/rdflib-4.2.2-py2.7.egg/rdflib/plugins/parsers/nquads.py", line 78, in parseline
    predicate = self.predicate()
  File "/usr/local/lib/python2.7/dist-packages/rdflib-4.2.2-py2.7.egg/rdflib/plugins/parsers/ntriples.py", line 222, in predicate
    pred = self.uriref()
  File "/usr/local/lib/python2.7/dist-packages/rdflib-4.2.2-py2.7.egg/rdflib/plugins/parsers/ntriples.py", line 238, in uriref
    return URI(uri)
  File "/usr/local/lib/python2.7/dist-packages/rdflib-4.2.2-py2.7.egg/rdflib/term.py", line 224, in __new__
    logger.warning('%s does not look like a valid URI, trying to serialize this will break.'%value)
  File "/usr/lib/python2.7/logging/__init__.py", line 1164, in warning
    self._log(WARNING, msg, args, **kwargs)
  File "/usr/lib/python2.7/logging/__init__.py", line 1271, in _log
    self.handle(record)
  File "/usr/lib/python2.7/logging/__init__.py", line 1281, in handle
    self.callHandlers(record)
  File "/usr/lib/python2.7/logging/__init__.py", line 1328, in callHandlers
    " \"%s\"\n" % self.name)
IOError: [Errno 5] Input/output error

Error: Triple:810838
Traceback (most recent call last):
  File "getResources.py", line 165, in processTriple
    g.parse(data=line,format="nquads")
  File "/usr/local/lib/python2.7/dist-packages/rdflib-4.2.2-py2.7.egg/rdflib/graph.py", line 1492, in parse
    context.parse(source, publicID=publicID, format=format, **args)
  File "/usr/local/lib/python2.7/dist-packages/rdflib-4.2.2-py2.7.egg/rdflib/graph.py", line 1039, in parse
    parser.parse(source, self, **args)
  File "/usr/local/lib/python2.7/dist-packages/rdflib-4.2.2-py2.7.egg/rdflib/plugins/parsers/nquads.py", line 64, in parse
    self.parseline()
  File "/usr/local/lib/python2.7/dist-packages/rdflib-4.2.2-py2.7.egg/rdflib/plugins/parsers/nquads.py", line 78, in parseline
    predicate = self.predicate()
  File "/usr/local/lib/python2.7/dist-packages/rdflib-4.2.2-py2.7.egg/rdflib/plugins/parsers/ntriples.py", line 222, in predicate
    pred = self.uriref()
  File "/usr/local/lib/python2.7/dist-packages/rdflib-4.2.2-py2.7.egg/rdflib/plugins/parsers/ntriples.py", line 238, in uriref
    return URI(uri)
  File "/usr/local/lib/python2.7/dist-packages/rdflib-4.2.2-py2.7.egg/rdflib/term.py", line 224, in __new__
    logger.warning('%s does not look like a valid URI, trying to serialize this will break.'%value)
  File "/usr/lib/python2.7/logging/__init__.py", line 1164, in warning
    self._log(WARNING, msg, args, **kwargs)
  File "/usr/lib/python2.7/logging/__init__.py", line 1271, in _log
    self.handle(record)
  File "/usr/lib/python2.7/logging/__init__.py", line 1281, in handle
    self.callHandlers(record)
  File "/usr/lib/python2.7/logging/__init__.py", line 1328, in callHandlers
    " \"%s\"\n" % self.name)
IOError: [Errno 5] Input/output error

Error: Triple:810838
Traceback (most recent call last):
  File "getResources.py", line 165, in processTriple
    g.parse(data=line,format="nquads")
  File "/usr/local/lib/python2.7/dist-packages/rdflib-4.2.2-py2.7.egg/rdflib/graph.py", line 1492, in parse
    context.parse(source, publicID=publicID, format=format, **args)
  File "/usr/local/lib/python2.7/dist-packages/rdflib-4.2.2-py2.7.egg/rdflib/graph.py", line 1039, in parse
    parser.parse(source, self, **args)
  File "/usr/local/lib/python2.7/dist-packages/rdflib-4.2.2-py2.7.egg/rdflib/plugins/parsers/nquads.py", line 64, in parse
    self.parseline()
  File "/usr/local/lib/python2.7/dist-packages/rdflib-4.2.2-py2.7.egg/rdflib/plugins/parsers/nquads.py", line 78, in parseline
    predicate = self.predicate()
  File "/usr/local/lib/python2.7/dist-packages/rdflib-4.2.2-py2.7.egg/rdflib/plugins/parsers/ntriples.py", line 222, in predicate
    pred = self.uriref()
  File "/usr/local/lib/python2.7/dist-packages/rdflib-4.2.2-py2.7.egg/rdflib/plugins/parsers/ntriples.py", line 238, in uriref
    return URI(uri)
  File "/usr/local/lib/python2.7/dist-packages/rdflib-4.2.2-py2.7.egg/rdflib/term.py", line 224, in __new__
    logger.warning('%s does not look like a valid URI, trying to serialize this will break.'%value)
  File "/usr/lib/python2.7/logging/__init__.py", line 1164, in warning
    self._log(WARNING, msg, args, **kwargs)
  File "/usr/lib/python2.7/logging/__init__.py", line 1271, in _log
    self.handle(record)
  File "/usr/lib/python2.7/logging/__init__.py", line 1281, in handle
    self.callHandlers(record)
  File "/usr/lib/python2.7/logging/__init__.py", line 1328, in callHandlers
    " \"%s\"\n" % self.name)
IOError: [Errno 5] Input/output error

Error: Triple:810840
Traceback (most recent call last):
  File "getResources.py", line 165, in processTriple
    g.parse(data=line,format="nquads")
  File "/usr/local/lib/python2.7/dist-packages/rdflib-4.2.2-py2.7.egg/rdflib/graph.py", line 1492, in parse
    context.parse(source, publicID=publicID, format=format, **args)
  File "/usr/local/lib/python2.7/dist-packages/rdflib-4.2.2-py2.7.egg/rdflib/graph.py", line 1039, in parse
    parser.parse(source, self, **args)
  File "/usr/local/lib/python2.7/dist-packages/rdflib-4.2.2-py2.7.egg/rdflib/plugins/parsers/nquads.py", line 64, in parse
    self.parseline()
  File "/usr/local/lib/python2.7/dist-packages/rdflib-4.2.2-py2.7.egg/rdflib/plugins/parsers/nquads.py", line 78, in parseline
    predicate = self.predicate()
  File "/usr/local/lib/python2.7/dist-packages/rdflib-4.2.2-py2.7.egg/rdflib/plugins/parsers/ntriples.py", line 222, in predicate
    pred = self.uriref()
  File "/usr/local/lib/python2.7/dist-packages/rdflib-4.2.2-py2.7.egg/rdflib/plugins/parsers/ntriples.py", line 238, in uriref
    return URI(uri)
  File "/usr/local/lib/python2.7/dist-packages/rdflib-4.2.2-py2.7.egg/rdflib/term.py", line 224, in __new__
    logger.warning('%s does not look like a valid URI, trying to serialize this will break.'%value)
  File "/usr/lib/python2.7/logging/__init__.py", line 1164, in warning
    self._log(WARNING, msg, args, **kwargs)
  File "/usr/lib/python2.7/logging/__init__.py", line 1271, in _log
    self.handle(record)
  File "/usr/lib/python2.7/logging/__init__.py", line 1281, in handle
    self.callHandlers(record)
  File "/usr/lib/python2.7/logging/__init__.py", line 1328, in callHandlers
    " \"%s\"\n" % self.name)
IOError: [Errno 5] Input/output error

Error: Triple:929353
Traceback (most recent call last):
  File "getResources.py", line 165, in processTriple
    g.parse(data=line,format="nquads")
  File "/usr/local/lib/python2.7/dist-packages/rdflib-4.2.2-py2.7.egg/rdflib/graph.py", line 1492, in parse
    context.parse(source, publicID=publicID, format=format, **args)
  File "/usr/local/lib/python2.7/dist-packages/rdflib-4.2.2-py2.7.egg/rdflib/graph.py", line 1039, in parse
    parser.parse(source, self, **args)
  File "/usr/local/lib/python2.7/dist-packages/rdflib-4.2.2-py2.7.egg/rdflib/plugins/parsers/nquads.py", line 64, in parse
    self.parseline()
  File "/usr/local/lib/python2.7/dist-packages/rdflib-4.2.2-py2.7.egg/rdflib/plugins/parsers/nquads.py", line 81, in parseline
    obj = self.object()
  File "/usr/local/lib/python2.7/dist-packages/rdflib-4.2.2-py2.7.egg/rdflib/plugins/parsers/ntriples.py", line 228, in object
    objt = self.uriref() or self.nodeid() or self.literal()
  File "/usr/local/lib/python2.7/dist-packages/rdflib-4.2.2-py2.7.egg/rdflib/plugins/parsers/ntriples.py", line 238, in uriref
    return URI(uri)
  File "/usr/local/lib/python2.7/dist-packages/rdflib-4.2.2-py2.7.egg/rdflib/term.py", line 224, in __new__
    logger.warning('%s does not look like a valid URI, trying to serialize this will break.'%value)
  File "/usr/lib/python2.7/logging/__init__.py", line 1164, in warning
    self._log(WARNING, msg, args, **kwargs)
  File "/usr/lib/python2.7/logging/__init__.py", line 1271, in _log
    self.handle(record)
  File "/usr/lib/python2.7/logging/__init__.py", line 1281, in handle
    self.callHandlers(record)
  File "/usr/lib/python2.7/logging/__init__.py", line 1328, in callHandlers
    " \"%s\"\n" % self.name)
IOError: [Errno 5] Input/output error

Error: Triple:1127501
Traceback (most recent call last):
  File "getResources.py", line 165, in processTriple
    g.parse(data=line,format="nquads")
  File "/usr/local/lib/python2.7/dist-packages/rdflib-4.2.2-py2.7.egg/rdflib/graph.py", line 1492, in parse
    context.parse(source, publicID=publicID, format=format, **args)
  File "/usr/local/lib/python2.7/dist-packages/rdflib-4.2.2-py2.7.egg/rdflib/graph.py", line 1039, in parse
    parser.parse(source, self, **args)
  File "/usr/local/lib/python2.7/dist-packages/rdflib-4.2.2-py2.7.egg/rdflib/plugins/parsers/nquads.py", line 64, in parse
    self.parseline()
  File "/usr/local/lib/python2.7/dist-packages/rdflib-4.2.2-py2.7.egg/rdflib/plugins/parsers/nquads.py", line 81, in parseline
    obj = self.object()
  File "/usr/local/lib/python2.7/dist-packages/rdflib-4.2.2-py2.7.egg/rdflib/plugins/parsers/ntriples.py", line 228, in object
    objt = self.uriref() or self.nodeid() or self.literal()
  File "/usr/local/lib/python2.7/dist-packages/rdflib-4.2.2-py2.7.egg/rdflib/plugins/parsers/ntriples.py", line 238, in uriref
    return URI(uri)
  File "/usr/local/lib/python2.7/dist-packages/rdflib-4.2.2-py2.7.egg/rdflib/term.py", line 224, in __new__
    logger.warning('%s does not look like a valid URI, trying to serialize this will break.'%value)
  File "/usr/lib/python2.7/logging/__init__.py", line 1164, in warning
    self._log(WARNING, msg, args, **kwargs)
  File "/usr/lib/python2.7/logging/__init__.py", line 1271, in _log
    self.handle(record)
  File "/usr/lib/python2.7/logging/__init__.py", line 1281, in handle
    self.callHandlers(record)
  File "/usr/lib/python2.7/logging/__init__.py", line 1328, in callHandlers
    " \"%s\"\n" % self.name)
IOError: [Errno 5] Input/output error

Error: Triple:1127502
Traceback (most recent call last):
  File "getResources.py", line 165, in processTriple
    g.parse(data=line,format="nquads")
  File "/usr/local/lib/python2.7/dist-packages/rdflib-4.2.2-py2.7.egg/rdflib/graph.py", line 1492, in parse
    context.parse(source, publicID=publicID, format=format, **args)
  File "/usr/local/lib/python2.7/dist-packages/rdflib-4.2.2-py2.7.egg/rdflib/graph.py", line 1039, in parse
    parser.parse(source, self, **args)
  File "/usr/local/lib/python2.7/dist-packages/rdflib-4.2.2-py2.7.egg/rdflib/plugins/parsers/nquads.py", line 64, in parse
    self.parseline()
  File "/usr/local/lib/python2.7/dist-packages/rdflib-4.2.2-py2.7.egg/rdflib/plugins/parsers/nquads.py", line 81, in parseline
    obj = self.object()
  File "/usr/local/lib/python2.7/dist-packages/rdflib-4.2.2-py2.7.egg/rdflib/plugins/parsers/ntriples.py", line 228, in object
    objt = self.uriref() or self.nodeid() or self.literal()
  File "/usr/local/lib/python2.7/dist-packages/rdflib-4.2.2-py2.7.egg/rdflib/plugins/parsers/ntriples.py", line 238, in uriref
    return URI(uri)
  File "/usr/local/lib/python2.7/dist-packages/rdflib-4.2.2-py2.7.egg/rdflib/term.py", line 224, in __new__
    logger.warning('%s does not look like a valid URI, trying to serialize this will break.'%value)
  File "/usr/lib/python2.7/logging/__init__.py", line 1164, in warning
    self._log(WARNING, msg, args, **kwargs)
  File "/usr/lib/python2.7/logging/__init__.py", line 1271, in _log
    self.handle(record)
  File "/usr/lib/python2.7/logging/__init__.py", line 1281, in handle
    self.callHandlers(record)
  File "/usr/lib/python2.7/logging/__init__.py", line 1328, in callHandlers
    " \"%s\"\n" % self.name)
IOError: [Errno 5] Input/output error

